<?xml version="1.0" ?>
<robot xmlns:xacro="http://www.ros.org/wiki/xacro">

  <link name="base_footprint"/>

  <link name="base_link">
    <visual>
      <origin xyz="0 0 0.4" rpy="${pi/2} 0 0"/>
      <geometry>
        <box size="0.8 0.79 0.6"/>
      </geometry>
      <material name="blue"/>
    </visual>

    <collision>
      <origin xyz="0 0 0.4" rpy="${pi/2} 0 0"/>
      <geometry>
        <box size="0.8 0.79 0.6"/>
      </geometry>
    </collision>

    <inertial>
      <origin xyz="0 0 0.4" rpy="${pi/2} 0 0"/>
      <mass value="18.33"/>
      <inertia ixx="2.277" ixy="0" ixz="0"
               iyy="2.559" iyz="0"
               izz="2.644" />
    </inertial>
  </link>

  <link name="Llanta_trasera_derecha_link">
    <visual>
      <origin xyz="0 -0.03 0" rpy="${pi/2} 0 0"/>
      <geometry>
        <cylinder radius="0.101" length="0.055" />
      </geometry>
      <material name="black"/>
    </visual>

    <collision>
      <origin xyz="0 -0.03 0" rpy="${pi/2} 0 0"/>
      <geometry>
        <cylinder radius="0.101" length="0.055" />
      </geometry>
    </collision>

    <inertial>
      <origin xyz="0 -0.03 0" rpy="${pi/2} 0 0"/>
      <mass value="1.150"/>
      <inertia ixx="0.0029" ixy="0" ixz="0"
               iyy="0.0029" iyz="0"
               izz="0.0042" />
    </inertial>
  </link>

  <link name="Llanta_trasera_izquierda_link">
    <visual>
      <origin xyz="0 0.03 0" rpy="${pi/2} 0 0"/>
      <geometry>
        <cylinder radius="0.101" length="0.055" />
      </geometry>
      <material name="black"/>
    </visual>

    <collision>
      <origin xyz="0 0.03 0" rpy="${pi/2} 0 0"/>
      <geometry>
        <cylinder radius="0.101" length="0.055" />
      </geometry>
    </collision>

    <inertial>
      <origin xyz="0 0.03 0" rpy="${pi/2} 0 0"/>
      <mass value="1.150"/>
      <inertia ixx="0.0029" ixy="0" ixz="0"
               iyy="0.0029" iyz="0"
               izz="0.0042" />
    </inertial>
  </link>

  <link name="Llanta_delantera_derecha_link">
    <visual>
      <origin xyz="0 -0.03 0" rpy="${pi/2} 0 0"/>
      <geometry>
        <cylinder radius="0.101" length="0.055" />
      </geometry>
      <material name="black"/>
    </visual>

    <collision>
      <origin xyz="0 -0.03 0" rpy="${pi/2} 0 0"/>
      <geometry>
        <cylinder radius="0.101" length="0.055" />
      </geometry>
    </collision>

    <inertial>
      <origin xyz="0 -0.03 0" rpy="${pi/2} 0 0"/>
      <mass value="0.974"/>
      <inertia ixx="0.0027" ixy="0" ixz="0"
               iyy="0.0027" iyz="0"
               izz="0.005" />
    </inertial>
  </link>

  <link name="Llanta_delantera_izquierda_link">
    <visual>
      <origin xyz="0 0.03 0" rpy="${pi/2} 0 0"/>
      <geometry>
        <cylinder radius="0.101" length="0.055" />
      </geometry>
      <material name="black"/>
    </visual>

    <collision>
      <origin xyz="0 0.03 0" rpy="${pi/2} 0 0"/>
      <geometry>
        <cylinder radius="0.101" length="0.055" />
      </geometry>
    </collision>

    <inertial>
      <origin xyz="0 0.03 0" rpy="${pi/2} 0 0"/>
      <mass value="0.974"/>
      <inertia ixx="0.0027" ixy="0" ixz="0"
               iyy="0.0027" iyz="0"
               izz="0.005" />
    </inertial>
  </link>

  <link name="Lidar_link">
    <visual>
      <origin xyz="0.02 0 0" rpy="${pi/2} 0 0"/>
      <geometry>
        <box size="0.032 0.035 0.046"/>
      </geometry>
      <material name="red"/>
    </visual>

    <collision>
      <origin xyz="0.02 0 0" rpy="${pi/2} 0 0"/>
      <geometry>
        <box size="0.032 0.035 0.046"/>
      </geometry>
    </collision>

    <inertial>
      <origin xyz="0.02 0 0" rpy="${pi/2} 0 0"/>
      <mass value="0.045"/>
      <inertia ixx="0.001" ixy="0" ixz="0"
               iyy="0.001" iyz="0"
               izz="0.001" />
    </inertial>
  </link>

  <link name="camara_link">
    <visual>
      <origin xyz="0.01 0 0" rpy="${pi/2} 0 0"/>
      <geometry>
        <box size="0.0175 0.028 0.091"/>
      </geometry>
      <material name="red"/>
    </visual>

    <collision>
      <origin xyz="0.01 0 0" rpy="${pi/2} 0 0"/>
      <geometry>
        <box size="0.0175 0.028 0.091"/>
      </geometry>
    </collision>

    <inertial>
      <origin xyz="0.01 0 0" rpy="${pi/2} 0 0"/>
      <mass value="0.020"/>
      <inertia ixx="0.001" ixy="0" ixz="0"
               iyy="0.001" iyz="0"
               izz="0.001" />
    </inertial>
  </link>


  <joint name="base_joint" type="fixed">
    <parent link="base_footprint"/>
    <child link="base_link" />
    <origin xyz="0 0 0.1" rpy="0 0 0"/>
  </joint>

  <joint name="base_llanta_trasera_derecha_joint" type="continuous">
    <parent link="base_link"/>
    <child link="Llanta_trasera_derecha_link" />
    <origin xyz="0.24 0.3 0" rpy="${pi} 0 0"/>
    <axis xyz="0 1 0" />
  </joint>

  <joint name="base_llanta_trasera_izquierda_joint" type="continuous">
    <parent link="base_link"/>
    <child link="Llanta_trasera_izquierda_link" />
    <origin xyz="0.24 -0.3 0" rpy="${pi} 0 0"/>
    <axis xyz="0 1 0" />
  </joint>

  <joint name="base_llanta_delantera_derecha_joint" type="fixed">
    <parent link="base_link"/>
    <child link="Llanta_delantera_derecha_link" />
    <origin xyz="-0.24 -0.3 0" rpy="0 0 0"/>
    <axis xyz="0 0 1" />
  </joint>

  <joint name="base_llanta_delantera_izquierda_joint" type="fixed">
    <parent link="base_link"/>
    <child link="Llanta_delantera_izquierda_link" />
    <origin xyz="-0.24 0.3 0" rpy="0 0 0"/>
    <axis xyz="0 0 1" />
  </joint>

  <joint name="base_Lidar_joint" type="fixed">
    <parent link="base_link"/>
    <child link="Lidar_link" />
    <origin xyz="-0.41 0 0.19" rpy="0 0 3.14"/>
  </joint>

  <joint name="base_camara_joint" type="fixed">
    <parent link="base_link"/>
    <child link="camara_link" />
    <origin xyz="-0.38 0 0.8" rpy="0 3.14 0"/>
  </joint>

</robot>